Workbook
Name AmortYrs: 'مصاريف ما قبل التشغيل'!$B$12
Name AssayCost: الافتراضات!$B$51
Name AvailFactor: الافتراضات!$B$18
Name BankGuar: الافتراضات!$B$34
Name BenchGrade: الافتراضات!$B$22
Name BrkProd: الافتراضات!$B$19
Name CifBench: الافتراضات!$B$21
Name CommunityRate: الافتراضات!$B$32
Name DieselPrice: الافتراضات!$B$46
Name DiscRate: الافتراضات!$B$59
Name EosRate: الافتراضات!$B$39
Name EqIns: الافتراضات!$B$48
Name ExpIns: الافتراضات!$B$40
Name F_Capex: 'تحليل الحساسية'!$B$8
Name F_Opex: 'تحليل الحساسية'!$B$7
Name F_Price: 'تحليل الحساسية'!$B$5
Name F_Vol: 'تحليل الحساسية'!$B$6
Name FxRate: الافتراضات!$B$9
Name GenAdmin: الافتراضات!$B$49
Name GuarComm: الافتراضات!$B$35
Name HaulDist: الافتراضات!$B$26
Name InflRate: الافتراضات!$B$47
Name K_IRR: 'المؤشرات المالية'!$B$7
Name K_IRRNew: 'المؤشرات المالية'!$B$13
Name K_NPV: 'المؤشرات المالية'!$B$6
Name K_NPVNew: 'المؤشرات المالية'!$B$12
Name K_Payback: 'المؤشرات المالية'!$B$8
Name LocalPrice: 'السوق والسعر'!$B$38
Name LocalShare: 'السوق والسعر'!$B$39
Name LicFees: التراخيص!$D$10
Name LicRenew: الافتراضات!$B$53
Name Loan: الافتراضات!$B$55
Name LoanRate: الافتراضات!$B$56
Name LoanYrs: الافتراضات!$B$57
Name MinExportGrade: 'السوق والسعر'!$B$13
Name MinWage: الافتراضات!$B$44
Name NatAvgOutput: 'السوق والسعر'!$B$11
Name NatAvgPrice: 'السوق والسعر'!$B$9
Name NewInv: 'التكلفة الاستثمارية والتمويل'!$B$12
Name OreGrade: الافتراضات!$B$13
Name OreReserve: الافتراضات!$B$12
Name Payroll: 'الموارد البشرية'!$G$17
Name Permit2: الافتراضات!$B$41
Name Permit3: الافتراضات!$B$42
Name PermitCost: 'الموارد البشرية'!$B$42
Name PermitOther: الافتراضات!$B$43
Name PermitRenew: 'الموارد البشرية'!$B$40
Name PortCost: الافتراضات!$B$24
Name PreOp: 'مصاريف ما قبل التشغيل'!$B$10
Name PriceDisc: الافتراضات!$B$28
Name PriceG: الافتراضات!$B$29
Name RehabCost: الافتراضات!$B$52
Name RoyaltyRate: الافتراضات!$B$31
Name SalePrice: 'السوق والسعر'!$B$41
Name SeaFreight: الافتراضات!$B$23
Name ShiftHrs: الافتراضات!$B$17
Name SiteRent: الإيجارات!$E$9
Name SortRecov: الافتراضات!$B$15
Name SPFEx: الافتراضات!$B$38
Name SPFOm: الافتراضات!$B$37

Sheet الغلاف والفهرس
B2: دراسة الجدوى الاقتصادية والفنية
B3: مشروع استخراج خام الكروم (محجر كروم) — محافظة شمال الشرقية، سلطنة عُمان
B4: Chromite Quarry Project — Technical & Economic Feasibility Study (updated, fully linked model)
B5: تاريخ التحديث: أكتوبر 2026 — العملة: ريال عُماني (ر.ع) — مدة الدراسة: سنة تأسيس + 5 سنوات تشغيل
A7: م | B7: الورقة | C7: المحتوى
A8: 1 | B8: الملخص التنفيذي | C8: الملخص التنفيذي: أهم الأرقام والمؤشرات والخلاصة
A9: 2 | B9: الافتراضات | C9: جميع الافتراضات والمدخلات الرئيسية مع مصدر كل رقم وحالته
A10: 3 | B10: التراخيص | C10: التراخيص المطلوبة ورسومها والإطار التنظيمي للقطاع
A11: 4 | B11: السوق والسعر | C11: بيانات السوق والأسعار المرجعية، وبناء سعر التصدير، والبيع المحلي وسعر البيع المعتمد
A12: 5 | B12: الخطة الفنية والإنتاج | C12: الطاقة الإنتاجية وبرنامج الإنتاج السنوي واستنزاف الاحتياطي
A13: 6 | B13: الإنتاج الشهري | C13: توزيع الإنتاج على 60 شهراً حسب أيام العمل، مع مطابقة المجاميع السنوية
A14: 7 | B14: الجدول الزمني | C14: مراحل وخطة تنفيذ المشروع بالتسلسل الصحيح (مخطط زمني)
A15: 8 | B15: الأصول والإهلاك | C15: الأصول الثابتة وجدول الإهلاك والاستبدال
A16: 9 | B16: مصاريف ما قبل التشغيل | C16: مصاريف ما قبل التشغيل وإطفاؤها
A17: 10 | B17: الموارد البشرية | C17: الأجور والرواتب والتأمينات ومأذونيات العمل
A18: 11 | B18: الإيجارات | C18: إيجار المواقع والمعدات والمركبات
A19: 12 | B19: المواد المستهلكة | C19: الوقود والمواد المستهلكة
... A28: 21 | B28: التصحيحات والمصادر | C28: ما تم تصحيحه في الدراسة الأصلية، البنود التي تحتاج تأكيداً، والمصادر
B29: دليل الألوان
B30: 1000 | C30: خلية مدخلات (خط أزرق وخلفية صفراء): يمكن تعديلها، وكل النتائج تُعاد احتسابها تلقائياً
B31: 1000 | C31: خلية محتسبة بمعادلة (خط أسود): لا تُعدَّل
B32: 1000 | C32: إجمالي
B33: 1000 | C33: نتيجة رئيسية
B35: تنبيه مهم
C36: نتائج هذه الدراسة تعتمد على افتراضات جيولوجية وسوقية لم ترد في الملف الأصلي (الاحتياطي، درجة الخام، نسبة التعرية، سعر البيع). يجب استبدالها بالأرقام الفعلية من التقرير الاستكشافي وعقد البيع قبل تقديم الدراسة لأي جهة — انظر ورقة «التصحيحات والمصادر».

Sheet الملخص التنفيذي
A1: الملخص التنفيذي
A2: جميع الأرقام مرتبطة بأوراق الدراسة وتتحدّث تلقائياً عند تعديل الافتراضات
A4: المؤشر | B4: القيمة | C4: الوحدة | D4: ملاحظات
A5: أولاً: المشروع
A6: الطاقة الإنتاجية — خام قابل للبيع | B6: =SaleCap -> 60000 | C6: طن/سنة | D6: معطى من المالك — 60,000 طن صافٍ سنوياً
A7: متوسط درجة الخام | B7: =OreGrade -> 0.32 | C7: Cr2O3 | D7: افتراض — يُستبدل بنتائج المختبر
A8: سعر البيع عند موقع التجميع | B8: =SalePrice -> 38.66 | C8: ر.ع/طن | D8: ="بيع محلي "&TEXT(LocalShare,"0%")&" + تصدير "&TEXT(1-LocalShare,"0%")&" — متوسط مرجّح من ورقة «السوق والسعر»" -> بيع محلي 100% + تصدير 0% — متوسط مرجّح من ورقة «السوق والسعر»
A9: عدد العاملين | B9: ='الموارد البشرية'!D17 -> 18 | C9: عامل
A10: نسبة التعمين | B10: ='الموارد البشرية'!B22 -> 0.55555556 | C10: %
A11: ثانياً: الاستثمار والتمويل
A12: إجمالي التكلفة الاستثمارية | B12: =TotalInv -> 504507.54 | C12: ر.ع | D12: أصول ثابتة + ما قبل التشغيل + ضمانات بنكية + رأس مال عامل
A13: منها: مصاريف استكشاف مدفوعة سابقاً | B13: =SunkCost -> 200000 | C13: ر.ع | D13: مساهمة المالك المنفذة خلال السنوات الثلاث الماضية
A14: الاستثمار الجديد المطلوب | B14: =NewInv -> 304507.54 | C14: ر.ع
A15: القرض البنكي المفترض | B15: =Loan -> 150000 | C15: ر.ع | D15: افتراض — يُعدَّل حسب شروط الجهة الممولة
A16: ثالثاً: التشغيل في السنة الثالثة (منتصف مدة الدراسة)
A17: الإيرادات | B17: =الإيرادات!F7 -> 2319600 | C17: ر.ع
A18: التكاليف التشغيلية النقدية (شاملة الإتاوة) | B18: ='التكاليف التشغيلية'!F31 -> 537366.43 | C18: ر.ع
A19: تكلفة الطن المباع | B19: ='التكاليف التشغيلية'!F32 -> 8.9561071 | C19: ر.ع/طن
A20: الربح قبل الفوائد والضرائب والإهلاك (EBITDA) | B20: ='قائمة الدخل'!F10 -> 1782233.6 | C20: ر.ع
A21: صافي الربح بعد الضريبة | B21: ='قائمة الدخل'!F20 -> 1460010.8 | C21: ر.ع
A22: رابعاً: مؤشرات الجدوى
A23: صافي القيمة الحالية (NPV) | B23: =K_NPV -> 5125634.4 | C23: ر.ع | D23: على إجمالي الاستثمار شاملاً المصاريف السابقة، عند معدل الخصم المعتمد
A24: معدل العائد الداخلي (IRR) | B24: =K_IRR -> 3.097682 | C24: % | D24: على إجمالي الاستثمار
A25: معدل العائد الداخلي على الاستثمار الجديد فقط | B25: =K_IRRNew -> 5.1443895 | C25: % | D25: باستبعاد المصاريف المدفوعة سابقاً (تكلفة غارقة)
A26: فترة الاسترداد | B26: =K_Payback -> 0.32109921 | C26: سنة | D26: من بداية الإنتاج
A27: سعر التعادل | B27: ='المؤشرات المالية'!B29 -> 8.2050398 | C27: ر.ع/طن | D27: السعر الذي يغطي جميع التكاليف في سنة التشغيل الكامل
A28: نسبة التعادل من الطاقة الإنتاجية | B28: ='المؤشرات المالية'!B28 -> 0.10662057 | C28: %
A29: خامساً: الخلاصة
A30: =IF(AND(ISNUMBER(K_IRR),K_NPV>0),"النتيجة: المشروع مجدٍ اقتصادياً وفق الافتراضات الحالية — صافي القيمة الحالية موجب ومعدل العائد الداخلي أعلى من معدل الخصم.","النتيجة: المشروع غير مجدٍ وفق الافتراضات الحالية — صافي القيمة الحالية سالب عند معدل الخصم المعتمد.") -> النتيجة: المشروع مجدٍ اقتصادياً وفق الافتراضات الحالية — صافي القيمة الحالية موجب ومعدل العائد الداخلي أعلى من معدل الخصم.
A31: 1) الجدوى شديدة الحساسية لسعر البيع والكمية المباعة (نسبة التعرية ودرجة الخام) — انظر «تحليل الحساسية».
A32: 2) الاحتياطي والدرجة ونسبة التعرية افتراضات يجب استبدالها بنتائج التقرير الاستكشافي المعتمد.
A33: 3) القرار الوزاري 18/2025: التصدير حصري عبر شركة متاجرة المعادن، ولا يُصدَّر الخام غير المعالج بدرجة أقل من 36%.
A34: 4) تفاصيل ما تم تصحيحه والبنود التي تحتاج تأكيداً في ورقة «التصحيحات والمصادر».
A35: ="5) الحفارات: "&'الخطة الفنية والإنتاج'!C14&" — الاحتياطي: "&'الخطة الفنية والإنتاج'!B28 -> 5) الحفارات: كافية — المطلوب 86% من طاقة الحفارات — الاحتياطي: الاحتياطي المفترض كافٍ لخمس سنوات تشغيل

Sheet الافتراضات
A1: الافتراضات والمدخلات الرئيسية
A2: الخلايا الصفراء بخط أزرق مدخلات قابلة للتعديل. عمود «المصدر / الحالة» يبيّن: من الدراسة الأصلية — مصدر منشور — افتراض يحتاج تأكيداً
A4: البند | B4: القيمة | C4: الوحدة | D4: المصدر / الحالة
A5: أولاً: بيانات عامة
A6: اسم المشروع | B6: محجر خام الكروم | C6: — | D6: من الدراسة الأصلية
A7: الموقع | B7: محافظة شمال الشرقية | C7: — | D7: من الدراسة الأصلية (الترخيص البلدي صادر من بلدية شمال الشرقية) — يُستكمل اسم الولاية ورقم الموقع وإحداثياته
A8: تاريخ بدء التنفيذ | B8: 46388 | C8: تاريخ | D8: افتراض — يُستخدم في الجدول الزمني فقط
A9: سعر صرف الدولار الأمريكي | B9: 0.3845 | C9: ر.ع / دولار | D9: سعر الربط الرسمي (1 ر.ع = 2.6008 دولار)
A10: مدة التشغيل في الدراسة | B10: 5 | C10: سنة | D10: ثابتة في بنية النموذج (سنة تأسيس + 5 سنوات تشغيل)
A11: ثانياً: الاحتياطي والإنتاج
A12: الاحتياطي القابل للتعدين | B12: 400000 | C12: طن خام | D12: معطى من المالك (أكتوبر 2026) — يُوثَّق بالتقرير الاستكشافي المعتمد
A13: متوسط نسبة أكسيد الكروم في الخام (Cr2O3) | B13: 0.32 | C13: % | D13: افتراض يحتاج تأكيداً — يُستبدل بنتائج تحاليل المختبر. الخام العُماني المتداول عالمياً غالباً 30–32%
A14: نسبة التعرية (طن صخور عقيمة لكل طن خام) | B14: 4 | C14: طن / طن | D14: معطى من المالك (أكتوبر 2026) — يحدد حجم الصخور المطلوب تحريكها وكفاية الحفارات
A15: نسبة استرداد الخام بعد الفرز اليدوي | B15: 0.85 | C15: % | D15: افتراض (الدراسة الأصلية تتضمن 5 عمال فرز)
A16: أيام العمل في السنة | B16: 312 | C16: يوم | D16: معطى من المالك: 6 أيام في الأسبوع × 52 أسبوعاً
A17: ساعات العمل اليومية | B17: 10 | C17: ساعة | D17: معطى من المالك: 10 ساعات يومياً. يتجاوز 9 ساعات للعامل في قانون العمل — يلزم عمل إضافي مدفوع أو نظام ورديتين للعمالة الميدانية
A18: معامل جاهزية واستغلال المعدات | B18: 0.75 | C18: % | D18: افتراض: يشمل الأعطال والصيانة وتوقفات الطقس والتنقل
A19: إنتاجية الحفار في التكسير والتحميل (للتحقق من الطاقة) | B19: 35 | C19: طن صخر / ساعة | D19: افتراض لصخور البريدوتيت/الدونيت — يُستخدم فقط للتحقق من كفاية الحفارات المستأجرة
A20: ثالثاً: السوق والسعر
A21: السعر المرجعي CIF الصين — كروم عُماني كتل 30–32% | B21: 200 | C21: دولار / طن | D21: مصدر منشور: SMM — 192.5 دولار (17 يونيو 2026) و205 دولار (30 سبتمبر 2026)؛ اعتُمد متوسط مقرَّب
A22: درجة الخام المرجعي (منتصف النطاق) | B22: 0.31 | C22: % | D22: منتصف نطاق 30–32% — يُستخدم لتحويل السعر إلى سعر وحدة الكروم
A23: أجور الشحن البحري عُمان – الصين | B23: 24 | C23: دولار / طن | D23: افتراض يحتاج تأكيداً (شحن سائب)
A24: مناولة وتخزين وتحميل في الميناء | B24: 2.5 | C24: ر.ع / طن | D24: افتراض يحتاج تأكيداً
A25: هامش التسويق والفحص والتمويل (المشتري/المصدِّر) | B25: 0.1 | C25: % من سعر CIF | D25: افتراض يحتاج تأكيداً — لم تُنشر بعد آلية تسعير شركة متاجرة المعادن للمنتجين
A26: مسافة النقل البري من موقع التجميع إلى الميناء | B26: 300 | C26: كم | D26: افتراض يحتاج تأكيداً حسب الموقع الفعلي والميناء (صحار / صلالة / الدقم)
A27: تعرفة النقل البري | B27: 0.02 | C27: ر.ع / طن.كم | D27: افتراض يحتاج تأكيداً بعروض شركات النقل
A28: خصم تحوّطي على صافي السعر | B28: 0.12 | C28: % | D28: تحوّط لتقلب الأسعار وغرامات الجودة والرطوبة؛ يقرّب السعر من المتوسط الوطني المحقق فعلياً
A29: التغير السنوي في سعر البيع | B29: 0 | C29: % سنوياً | D29: افتراض متحفظ: ثبات السعر مع تضخم التكاليف
A30: رابعاً: الرسوم الحكومية والضرائب
A31: الإتاوة الحكومية | B31: 0.05 | C31: % من قيمة الإنتاج | D31: قانون الثروة المعدنية (م.س 19/2019): لا تقل عن 5% — تُؤكَّد النسبة المحددة في الترخيص
A32: مساهمة تنمية المجتمع المحلي | B32: 0.01 | C32: % من قيمة الإنتاج | D32: قانون الثروة المعدنية: لا تقل عن 1%
A33: ضريبة الدخل | B33: 0.15 | C33: % من الربح | D33: قانون ضريبة الدخل: 15% (نسبة 3% للمؤسسات الصغيرة لا تنطبق على استخراج الثروات الطبيعية)
A34: الضمانات البنكية (وزارة الطاقة والمعادن / هيئة البيئة) | B34: 55000 | C34: ر.ع | D34: من الدراسة الأصلية — عولجت كوديعة مستردة في نهاية المشروع لا كمصروف
A35: عمولة الضمان البنكي السنوية | B35: 0.015 | C35: % سنوياً | D35: افتراض يحتاج تأكيداً من البنك
A36: خامساً: العمالة
A37: اشتراك صاحب العمل في صندوق الحماية الاجتماعية — العمانيون | B37: 0.145 | C37: % من الأجر | D37: مصدر منشور: شيخوخة وعجز ووفاة 11% + إصابات عمل 1% + أمان وظيفي 0.5% + أمومة 1% + إجازات مرضية 1% (من يوليو 2026)
A38: اشتراكات صاحب العمل — الوافدون | B38: 0.03 | C38: % من الأجر | D38: أمومة 1% + إصابات عمل 1% + إجازات مرضية 1% — يُتحقق من الصندوق
A39: مخصص نهاية الخدمة / نظام الادخار للوافدين | B39: 0.09 | C39: % من الأجر | D39: نظام الادخار 9% اعتباراً من يوليو 2027 (وقبله مكافأة نهاية الخدمة: راتب شهر عن كل سنة)
A40: التأمين الصحي وتأمين العمال للوافد | B40: 400 | C40: ر.ع / عامل / سنة | D40: من الدراسة الأصلية (4,800 ÷ 12 عاملاً)
A41: رسوم مأذونية العمل — مهن الفئة الثانية | B41: 251 | C41: ر.ع / سنتين | D41: مصدر منشور: قرار وزارة العمل 602/2025 (صلاحية 24 شهراً)
...

Sheet التراخيص
A1: التراخيص اللازمة لمزاولة النشاط والإطار التنظيمي
A2: الرسوم من الدراسة الأصلية — تُراجع مع جدول الرسوم الساري لدى وزارة الطاقة والمعادن وهيئة البيئة قبل التقديم
A4: م | B4: الترخيص | C4: الجهة المانحة | D4: الرسوم (ر.ع) | E4: المرحلة | F4: متطلبات الحصول على الترخيص
A5: 1 | B5: ترخيص التنقيب | C5: وزارة الطاقة والمعادن | D5: 2000 | E5: الاستكشاف (منجز) | F5: موافقة الجهات المختصة على الموقع المحدد: هيئة البيئة، وزارة الإسكان والتخطيط العمراني، وزارة التراث والسياحة، شرطة عُمان السلطانية، وزارة الدفاع، وزارة الثروة الزراعية والسمكية وموارد المياه، وزارة الداخلية
A6: 2 | B6: التصريح البيئي للتنقيب | C6: هيئة البيئة | D6: 400 | E6: الاستكشاف (منجز) | F6: موافقة وزارة الطاقة والمعادن، ودراسة بيئية تثبت عدم وجود تأثيرات بيئية في الموقع
A7: 3 | B7: ترخيص التعدين | C7: وزارة الطاقة والمعادن | D7: 5500 | E7: قبل الإنتاج | F7: تقرير تنقيبي شامل (الحفر والعينات)، تقدير الاحتياطي، دراسة الجدوى وخطة التعدين، الضمان المالي
A8: 4 | B8: التصريح البيئي للتعدين | C8: هيئة البيئة | D8: 400 | E8: قبل الإنتاج | F8: صدور الموافقة على ترخيص التعدين، ودراسة الأثر البيئي وخطة إعادة التأهيل
A9: 5 | B9: الترخيص البلدي | C9: بلدية شمال الشرقية | D9: 100 | E9: قبل الإنتاج | F9: السجل التجاري وعقود إيجار المواقع
A10: إجمالي تكلفة إصدار التراخيص | D10: =SUM(D5:D9) -> 8400
A12: الإطار التنظيمي الذي بُنيت عليه الدراسة
A13: م | B13: الموضوع | C13: المرجع | D13: الحكم وأثره في الدراسة
A14: 1 | B14: الإتاوة | C14: قانون الثروة المعدنية (م.س 19/2019) | F14: لا تقل عن 5% من إجمالي الإنتاج السنوي للخام المستغل. اعتُمدت 5% في الدراسة، وتُؤكَّد النسبة المحددة في ترخيص المشروع.
A15: 2 | B15: مساهمة تنمية المجتمع المحلي | C15: قانون الثروة المعدنية | F15: لا تقل عن 1% من الإنتاج السنوي تُدفع للجهة التي يحددها مجلس الوزراء. اعتُمدت 1%.
A16: 3 | B16: الضمان المالي والإيجار السنوي | C16: قانون الثروة المعدنية | F16: ضمان مالي لا يقل عن 1% من تكلفة المشروع قبل إصدار الترخيص، وإيجار سنوي للمساحة المرخصة. الدراسة تعتمد ضمانات بقيمة 55,000 ر.ع كما في الملف الأصلي.
A17: 4 | B17: تصدير خام الكروم | C17: قرار وزارة الطاقة والمعادن 18/2025 | F17: الحق الحصري في التصدير لشركة متاجرة المعادن (تابعة لشركة تنمية معادن عُمان)؛ لا يُصدَّر الخام بتركيز أقل من 36% ما لم يكن معالجاً وبموافقة كتابية من الوزارة؛ وللسوق المحلي حق الأولوية في الشراء. نافذ منذ منتصف 2026.
A18: 5 | B18: ضريبة الدخل | C18: قانون ضريبة الدخل | F18: 15% على الربح الخاضع للضريبة. النسبة المخفضة 3% للمؤسسات الصغيرة لا تشمل أنشطة استخراج الثروات الطبيعية.
A19: 6 | B19: ضريبة القيمة المضافة | C19: قانون ضريبة القيمة المضافة | F19: 5% على المبيعات المحلية والصادرات بنسبة صفر. تُحصَّل من المشتري وتُسترد على المشتريات، لذلك لم تُدرج ضمن التكاليف.
A20: 7 | B20: مأذونيات العمل | C20: قرار وزارة العمل 602/2025 | F20: صلاحية 24 شهراً؛ الرسوم 301 / 251 / 201 ر.ع حسب فئة المهنة؛ تخفيض 30% عند الالتزام بنسب التعمين ومضاعفتها عند عدم الالتزام.
A21: 8 | B21: الحماية الاجتماعية | C21: قانون الحماية الاجتماعية (م.س 52/2023) | F21: اشتراك صاحب العمل عن العُماني 14.5% من الأجر، واشتراكات الأمومة وإصابات العمل والإجازات المرضية عن الوافد، ونظام ادخار للوافدين 9% من يوليو 2027.

Sheet السوق والسعر
A1: تحليل السوق وبناء سعر البيع
A2: السعر المعتمد يُحتسب بطريقة صافي العائد (Netback) من السعر المرجعي العالمي نزولاً إلى موقع التجميع
A4: البند | B4: القيمة | C4: الوحدة | D4: المصدر / ملاحظات
A5: أولاً: سوق خام الكروم في سلطنة عُمان
A6: إنتاج السلطنة من خام الكروم (2025) | B6: 353538 | C6: طن | D6: وزارة الطاقة والمعادن — منشور في Times of Oman
A7: مبيعات خام الكروم (2025) | B7: 387995 | C7: طن | D7: المصدر نفسه
A8: قيمة المبيعات (2025) | B8: 15000000 | C8: ر.ع | D8: «تجاوزت 15 مليون ر.ع» — المصدر نفسه
A9: متوسط السعر المحقق وطنياً (2025) | B9: =B8/B7 -> 38.660292 | C9: ر.ع / طن | D9: محتسب: يشمل جميع الدرجات والمبيعات المحلية والتصدير — رقم مرجعي للتحقق من واقعية سعر الدراسة
A10: عدد المحاجر العاملة | B10: 29 | C10: محجر | D10: من ولاية شناص إلى ولاية وادي بني خالد
A11: متوسط إنتاج المحجر الواحد | B11: =B6/B10 -> 12190.966 | C11: طن / سنة | D11: محتسب — يُقارن بالطاقة الإنتاجية للمشروع
A12: الإنتاج المستهدف للسلطنة بحلول 2030 | B12: 400000 | C12: طن / سنة | D12: شركة تنمية معادن عُمان — Oman Observer
A13: الحد الأدنى لدرجة تصدير الخام غير المعالج | B13: 0.36 | C13: Cr2O3 | D13: القرار الوزاري 18/2025 — التصدير حصري عبر شركة متاجرة المعادن، وللسوق المحلي حق الأولوية
A14: ثانياً: الأسعار المرجعية العالمية — CIF الصين (SMM، 30 سبتمبر 2026)
A15: كروم عُماني كتل 30–32% | B15: 205 | C15: دولار / طن | D15: النطاق 200–210 (وكان 192.5 في 17 يونيو 2026)
A16: كروم جنوب أفريقيا كتل 38% | B16: 257.5 | C16: دولار / طن | D16: النطاق 255–260
A17: مركزات جنوب أفريقيا 40–42% | B17: 267.5 | C17: دولار / طن | D17: النطاق 265–270
A18: كروم تركي كتل 40–42% | B18: 340 | C18: دولار / طن | D18: النطاق 335–345 — يوضح علاوة الدرجات العالية والكتل الصلبة
A19: ثالثاً: بناء سعر البيع المعتمد (صافي العائد عند موقع التجميع)
A20: السعر المرجعي CIF الصين للخام 30–32% | B20: =CifBench -> 200 | C20: دولار / طن | D20: من ورقة الافتراضات
A21: سعر وحدة الكروم (لكل 1% Cr2O3) | B21: =B20/(BenchGrade*100) -> 6.4516129 | C21: دولار / وحدة | D21: السعر المرجعي ÷ درجة الخام المرجعي
A22: درجة خام المشروع | B22: =OreGrade -> 0.32 | C22: Cr2O3 | D22: من ورقة الافتراضات
A23: السعر المعادل CIF لخام المشروع | B23: =B21*B22*100 -> 206.45161 | C23: دولار / طن
A24: السعر المعادل CIF لخام المشروع | B24: =B23*FxRate -> 79.380645 | C24: ر.ع / طن
A25: (-) الشحن البحري | B25: =SeaFreight*FxRate -> 9.228 | C25: ر.ع / طن
A26: (-) المناولة والتخزين والتحميل في الميناء | B26: =PortCost -> 2.5 | C26: ر.ع / طن
A27: (-) هامش التسويق والفحص والتمويل | B27: =B24*TraderM -> 7.9380645 | C27: ر.ع / طن
A28: صافي السعر تسليم الميناء | B28: =B24-B25-B26-B27 -> 59.714581 | C28: ر.ع / طن
A29: (-) النقل البري من موقع التجميع إلى الميناء | B29: =HaulDist*TruckRate -> 6 | C29: ر.ع / طن
A30: صافي العائد عند موقع التجميع | B30: =B28-B29 -> 53.714581 | C30: ر.ع / طن
A31: (-) الخصم التحوّطي | B31: =B30*PriceDisc -> 6.4457497 | C31: ر.ع / طن
A32: صافي سعر التصدير عند موقع التجميع | B32: =B30-B31 -> 47.268831 | C32: ر.ع / طن | D32: يُستخدم لحصة التصدير فقط — انظر «خامساً» أدناه
A33: رابعاً: التحقق
A34: نسبة سعر الدراسة إلى المتوسط الوطني المحقق 2025 | B34: =SalePrice/NatAvgPrice -> 0.99999245 | C34: مرة | D34: =IF(ABS(B34-1)<0.005,"السعر المعتمد يساوي المتوسط الوطني المحقق 2025.",IF(B34>1,"السعر المعتمد أعلى من المتوسط الوطني المحقق 2025 — يُبرَّر بعقد أو عرض شراء.","السعر المعتمد أقل من المتوسط الوطني المحقق 2025 (تحفّظ).")) -> السعر المعتمد يساوي المتوسط الوطني المحقق 2025.
A35: هل تحقق درجة الخام شرط تصدير الخام غير المعالج؟ | B35: =IF(OreGrade>=MinExportGrade,"نعم","لا") -> لا | C35: — | D35: =IF(OreGrade>=MinExportGrade,"الدرجة مطابقة لشرط التصدير (36% فأكثر).","تنبيه: الدرجة أقل من 36% — لا يُسمح بتصدير الخام غير المعالج. يُباع محلياً (مصانع المعالجة/الفيروكروم) أو يُعالَج ويُصدَّر عبر شركة متاجرة المعادن بموافقة الوزارة، وقد ينخفض السعر المحقق عن المحتسب أعلاه.") -> تنبيه: الدرجة أقل من 36% — لا يُسمح بتصدير الخام غير المعالج. يُباع محلياً (مصانع المعالجة/الفيروكروم) أو يُعالَج ويُصدَّر عبر شركة متاجرة المعادن بموافقة الوزارة، وقد ينخفض السعر المحقق عن المحتسب أعلاه.
A37: خامساً: مسار البيع — بيع محلي و/أو تصدير
A38: سعر البيع المحلي عند موقع التجميع | B38: 38.66 | C38: ر.ع / طن | D38: افتراض يحتاج تأكيداً = متوسط السعر الوطني المحقق 2025 (B9). يُستبدل بعرض مشترٍ محلي (مصانع المعالجة / الفيروكروم) تسليم موقع التجميع
A39: نسبة المبيعات المحلية من الكمية المباعة | B39: 1 | C39: % | D39: 100% = بيع محلي بالكامل (الحالة الأساسية لأن درجة الخام أقل من 36%). الباقي يُصدَّر عبر شركة متاجرة المعادن بصافي سعر التصدير
A40: صافي سعر التصدير عند موقع التجميع | B40: =B32 -> 47.268831 | C40: ر.ع / طن | D40: من «ثالثاً» أعلاه
A41: سعر البيع المعتمد في الدراسة (متوسط مرجّح) | B41: =B38*B39+B40*(1-B39) -> 38.66 | C41: ر.ع / طن | D41: يُستخدم في الإيرادات وجميع المؤشرات والحساسية
A42: التحقق من شرط درجة التصدير | B42: =IF(OR(B39>=1,OreGrade>=MinExportGrade),"مطابق","مخالف") -> مطابق | C42: — | D42: =IF(B39>=1,"البيع محلي بالكامل — لا ينطبق شرط درجة التصدير.",IF(OreGrade>=MinExportGrade,"الدرجة تسمح بتصدير الخام غير المعالج عبر شركة متاجرة المعادن.","تنبيه: جزء من المبيعات مفترض للتصدير والدرجة أقل من 36% — يلزم معالجة الخام وموافقة الوزارة، أو رفع نسبة البيع المحلي إلى 100%.")) -> البيع محلي بالكامل — لا ينطبق شرط درجة التصدير.

Sheet الخطة الفنية والإنتاج
A1: الخطة الفنية وبرنامج الإنتاج
A2: محجر كروم جبلي — تتبع العروق بالحفر والقطع إلى باطن الأرض بحفارات مستأجرة بالساعة — فرز يدوي — بيع من موقع التجميع
A4: البند | B4: الوحدة | C4: القيمة | D4: ملاحظات
A5: عدد الحفارات المستأجرة (شاملة المشغل والديزل) | B5: عدد | C5: =ExcavNo -> 5 | D5: من «الافتراضات» — معطى من المالك
A6: ساعات العمل المجدولة للمعدة في السنة | B6: ساعة | C6: =WorkDays*ShiftHrs -> 3120 | D6: أيام العمل × ساعات العمل اليومية (312 × 10)
A7: ساعات التشغيل الفعلية للمعدة | B7: ساعة | C7: =C6*AvailFactor -> 2340 | D7: بعد معامل الجاهزية — تُستخدم لوقود المعدات المملوكة وللتحقق من الطاقة
A8: الخام القابل للبيع المستهدف (الطاقة الإنتاجية) | B8: طن | C8: =TargetProd -> 60000 | D8: معطى من المالك: 60,000 طن صافٍ سنوياً
A9: الخام الخارج من المحجر المطلوب (ROM) | B9: طن | C9: =SaleCap/SortRecov -> 70588.235 | D9: الصافي ÷ نسبة الاسترداد بعد الفرز
A10: إجمالي الصخور المطلوب تحريكها (خام + عقيم) | B10: طن | C10: =ROMCap*(1+StripRatio) -> 352941.18 | D10: ROM × (1 + نسبة التعرية)
A11: الصخور العقيمة | B11: طن | C11: =RockCap-ROMCap -> 282352.94
A12: طاقة الحفارات على التكسير والتحميل | B12: طن | C12: =C5*BrkProd*C7 -> 409500 | D12: عدد الحفارات × الإنتاجية × ساعات التشغيل الفعلية
A13: الصخور المطلوبة إلى طاقة الحفارات | B13: % | C13: =IF(C12>0,C10/C12,0) -> 0.86188321 | D13: أكثر من 100% = الحفارات لا تكفي عند نسبة التعرية المفترضة
A14: التحقق من كفاية الحفارات | C14: =IF(C13<=1,"كافية — المطلوب "&TEXT(C13,"0%")&" من طاقة الحفارات","غير كافية — المطلوب "&TEXT(C13,"0%")&" من طاقتها؛ يلزم ألا تزيد نسبة التعرية عن "&TEXT(C15,"0.0")&" أو إنتاجية أعلى أو حفارات إضافية") -> كافية — المطلوب 86% من طاقة الحفارات
A15: أقصى نسبة تعرية تسمح بها طاقة الحفارات | B15: طن / طن | C15: =IF(ROMCap>0,C12/ROMCap-1,0) -> 4.80125 | D15: للمقارنة بنسبة التعرية في «الافتراضات»
A16: للمقارنة: متوسط إنتاج المحجر الواحد في السلطنة (2025) | B16: طن | C16: =NatAvgOutput -> 12190.966 | D16: 353,538 طن ÷ 29 محجراً — من ورقة «السوق والسعر»
A17: عمر الاحتياطي المفترض عند الطاقة الكاملة | B17: سنة | C17: =IF(ROMCap>0,OreReserve/ROMCap,0) -> 5.6666667 | D17: الاحتياطي ÷ الخام المستخرج سنوياً
A19: برنامج الإنتاج السنوي | B19: الوحدة | C19: 0 | D19: 1 | E19: 2 | F19: 3 | G19: 4 | H19: 5 | I19: الإجمالي
A20: نسبة استغلال الطاقة الإنتاجية | B20: % | D20: 1 | E20: 1 | F20: 1 | G20: 1 | H20: 1
A21: نسبة الأعباء الإضافية لتتبع العروق إلى باطن الأرض | B21: % | D21: 0 | E21: 0.1 | F21: 0.2 | G21: 0.3 | H21: 0.4
A22: إجمالي الصخور المحفورة | B22: طن | D22: =RockCap*D20 -> 352941.18 | E22: =RockCap*E20 -> 352941.18 | F22: =RockCap*F20 -> 352941.18 | G22: =RockCap*G20 -> 352941.18 | H22: =RockCap*H20 -> 352941.18 | I22: =SUM(D22:H22) -> 1764705.9
A23: الخام الخارج من المحجر (ROM) | B23: طن | D23: =ROMCap*D20 -> 70588.235 | E23: =ROMCap*E20 -> 70588.235 | F23: =ROMCap*F20 -> 70588.235 | G23: =ROMCap*G20 -> 70588.235 | H23: =ROMCap*H20 -> 70588.235 | I23: =SUM(D23:H23) -> 352941.18
A24: الخام القابل للبيع | B24: طن | D24: =D23*SortRecov*F_Vol -> 60000 | E24: =E23*SortRecov*F_Vol -> 60000 | F24: =F23*SortRecov*F_Vol -> 60000 | G24: =G23*SortRecov*F_Vol -> 60000 | H24: =H23*SortRecov*F_Vol -> 60000 | I24: =SUM(D24:H24) -> 300000
A25: ساعات إيجار الحفارات (شاملة أعباء تتبع العروق) | B25: ساعة | D25: =ExcavNo*SchedHrs*D20*(1+D21) -> 15600 | E25: =ExcavNo*SchedHrs*E20*(1+E21) -> 17160 | F25: =ExcavNo*SchedHrs*F20*(1+F21) -> 18720 | G25: =ExcavNo*SchedHrs*G20*(1+G21) -> 20280 | H25: =ExcavNo*SchedHrs*H20*(1+H21) -> 21840 | I25: =SUM(D25:H25) -> 93600
A26: الاستنزاف التراكمي للاحتياطي | B26: طن | D26: =SUM($D$23:D23) -> 70588.235 | E26: =SUM($D$23:E23) -> 141176.47 | F26: =SUM($D$23:F23) -> 211764.71 | G26: =SUM($D$23:G23) -> 282352.94 | H26: =SUM($D$23:H23) -> 352941.18
A27: الاحتياطي المتبقي آخر السنة | B27: طن | C27: =OreReserve -> 400000 | D27: =OreReserve-D26 -> 329411.76 | E27: =OreReserve-E26 -> 258823.53 | F27: =OreReserve-F26 -> 188235.29 | G27: =OreReserve-G26 -> 117647.06 | H27: =OreReserve-H26 -> 47058.824
A28: كفاية الاحتياطي لمدة الدراسة | B28: =IF($H$27>=0,"الاحتياطي المفترض كافٍ لخمس سنوات تشغيل","تنبيه: الاحتياطي المفترض ("&TEXT(OreReserve,"#,##0")&" طن) لا يكفي — المطلوب "&TEXT($H$26,"#,##0")&" طن خام لخمس سنوات") -> الاحتياطي المفترض كافٍ لخمس سنوات تشغيل
A29: نسبة الأعباء الإضافية تمثل الزيادة في ساعات الحفر والقطع والتحميل مع تعمّق العروق (ممرات أضيق، مسافات نقل أطول، تدعيم وتصريف مياه). تُطبَّق على إيجار الحفارات والمواد المستهلكة المتغيرة — قيم تقديرية قابلة للتعديل.
A31: أسلوب التعدين وتسلسل العمليات
A32: 1) محجر جبلي مكشوف في المرحلة الأولى، ثم تتبع عروق الكروم بالحفر والقطع إلى باطن الأرض ابتداءً من السنة الثانية.
A33: 2) التكسير والقطع والتحميل بخمسة حفارات مستأجرة بالساعة (12 ر.ع/ساعة شاملة المعدة والمشغل والديزل)، 10 ساعات يومياً و6 أيام أسبوعياً.
A34: 3) نقل الخام بقلاب مملوك إلى ساحة الفرز، والتجميع والتحميل بشيول مملوك؛ العقيم يُزاح ويُرصّ في المرمى بالحفارات.
A35: 4) فرز وتنقية الخام يدوياً لرفع الدرجة، ثم أخذ العينات وتحليلها والبيع من موقع التجميع.
A36: 5) إعادة تأهيل تدريجية وفق التصريح البيئي وخطة الإغلاق.
A37: ملاحظة: الأعمال تحت السطح قد تتطلب اشتراطات سلامة وموافقات إضافية من وزارة الطاقة والمعادن — تُؤكَّد قبل التنفيذ. الدراسة لا تتضمن تفجيراً.

Sheet الإنتاج الشهري
A1: برنامج الإنتاج الشهري
A2: يوزّع الإنتاج السنوي من «الخطة الفنية والإنتاج» على الأشهر بحسب أيام العمل في كل شهر. السنة الأولى تبدأ من شهر بدء الإنتاج في «الجدول الزمني». الخلايا الصفراء فقط قابلة للتعديل.
A4: أولاً: الإنتاج الشهري — 5 سنوات تشغيل (60 شهراً) | M4: ثانياً: أيام العمل في كل شهر
A5: الشهر | B5: سنة التشغيل | C5: رقم الشهر | D5: أيام العمل | E5: نسبة استغلال الطاقة | F5: إجمالي الصخور المحفورة (طن) | G5: الخام الخارج من المحجر ROM (طن) | H5: الخام القابل للبيع (طن) | I5: متوسط الإنتاج اليومي القابل للبيع (طن/يوم) | J5: الخام القابل للبيع — تراكمي (طن) | K5: الاحتياطي المتبقي آخر الشهر (طن) | M5: الشهر | N5: أيام العمل
A6: =EDATE($N$21,C6-1) -> 46661 | B6: =INT((C6-1)/12)+1 -> 1 | C6: 1 | D6: =INDEX($N$6:$N$17,MONTH(A6)) -> 26 | E6: =INDEX('الخطة الفنية والإنتاج'!$D$20:$H$20,B6) -> 1 | F6: =IF($N$18>0,INDEX('الخطة الفنية والإنتاج'!$D$22:$H$22,B6)*D6/$N$18,0) -> 29411.765 | G6: =IF($N$18>0,INDEX('الخطة الفنية والإنتاج'!$D$23:$H$23,B6)*D6/$N$18,0) -> 5882.3529 | H6: =IF($N$18>0,INDEX('الخطة الفنية والإنتاج'!$D$24:$H$24,B6)*D6/$N$18,0) -> 5000 | I6: =IF(D6>0,H6/D6,0) -> 192.30769 | J6: =SUM($H$6:H6) -> 5000 | K6: =OreReserve-SUM($G$6:G6) -> 394117.65 | M6: يناير | N6: 26
A7: =EDATE($N$21,C7-1) -> 46692 | B7: =INT((C7-1)/12)+1 -> 1 | C7: 2 | D7: =INDEX($N$6:$N$17,MONTH(A7)) -> 26 | E7: =INDEX('الخطة الفنية والإنتاج'!$D$20:$H$20,B7) -> 1 | F7: =IF($N$18>0,INDEX('الخطة الفنية والإنتاج'!$D$22:$H$22,B7)*D7/$N$18,0) -> 29411.765 | G7: =IF($N$18>0,INDEX('الخطة الفنية والإنتاج'!$D$23:$H$23,B7)*D7/$N$18,0) -> 5882.3529 | H7: =IF($N$18>0,INDEX('الخطة الفنية والإنتاج'!$D$24:$H$24,B7)*D7/$N$18,0) -> 5000 | I7: =IF(D7>0,H7/D7,0) -> 192.30769 | J7: =SUM($H$6:H7) -> 10000 | K7: =OreReserve-SUM($G$6:G7) -> 388235.29 | M7: فبراير | N7: 26
A8: =EDATE($N$21,C8-1) -> 46722 | B8: =INT((C8-1)/12)+1 -> 1 | C8: 3 | D8: =INDEX($N$6:$N$17,MONTH(A8)) -> 26 | E8: =INDEX('الخطة الفنية والإنتاج'!$D$20:$H$20,B8) -> 1 | F8: =IF($N$18>0,INDEX('الخطة الفنية والإنتاج'!$D$22:$H$22,B8)*D8/$N$18,0) -> 29411.765 | G8: =IF($N$18>0,INDEX('الخطة الفنية والإنتاج'!$D$23:$H$23,B8)*D8/$N$18,0) -> 5882.3529 | H8: =IF($N$18>0,INDEX('الخطة الفنية والإنتاج'!$D$24:$H$24,B8)*D8/$N$18,0) -> 5000 | I8: =IF(D8>0,H8/D8,0) -> 192.30769 | J8: =SUM($H$6:H8) -> 15000 | K8: =OreReserve-SUM($G$6:G8) -> 382352.94 | M8: مارس | N8: 26
A9: =EDATE($N$21,C9-1) -> 46753 | B9: =INT((C9-1)/12)+1 -> 1 | C9: 4 | D9: =INDEX($N$6:$N$17,MONTH(A9)) -> 26 | E9: =INDEX('الخطة الفنية والإنتاج'!$D$20:$H$20,B9) -> 1 | F9: =IF($N$18>0,INDEX('الخطة الفنية والإنتاج'!$D$22:$H$22,B9)*D9/$N$18,0) -> 29411.765 | G9: =IF($N$18>0,INDEX('الخطة الفنية والإنتاج'!$D$23:$H$23,B9)*D9/$N$18,0) -> 5882.3529 | H9: =IF($N$18>0,INDEX('الخطة الفنية والإنتاج'!$D$24:$H$24,B9)*D9/$N$18,0) -> 5000 | I9: =IF(D9>0,H9/D9,0) -> 192.30769 | J9: =SUM($H$6:H9) -> 20000 | K9: =OreReserve-SUM($G$6:G9) -> 376470.59 | M9: أبريل | N9: 26
A10: =EDATE($N$21,C10-1) -> 46784 | B10: =INT((C10-1)/12)+1 -> 1 | C10: 5 | D10: =INDEX($N$6:$N$17,MONTH(A10)) -> 26 | E10: =INDEX('الخطة الفنية والإنتاج'!$D$20:$H$20,B10) -> 1 | F10: =IF($N$18>0,INDEX('الخطة الفنية والإنتاج'!$D$22:$H$22,B10)*D10/$N$18,0) -> 29411.765 | G10: =IF($N$18>0,INDEX('الخطة الفنية والإنتاج'!$D$23:$H$23,B10)*D10/$N$18,0) -> 5882.3529 | H10: =IF($N$18>0,INDEX('الخطة الفنية والإنتاج'!$D$24:$H$24,B10)*D10/$N$18,0) -> 5000 | I10: =IF(D10>0,H10/D10,0) -> 192.30769 | J10: =SUM($H$6:H10) -> 25000 | K10: =OreReserve-SUM($G$6:G10) -> 370588.24 | M10: مايو | N10: 26
A11: =EDATE($N$21,C11-1) -> 46813 | B11: =INT((C11-1)/12)+1 -> 1 | C11: 6 | D11: =INDEX($N$6:$N$17,MONTH(A11)) -> 26 | E11: =INDEX('الخطة الفنية والإنتاج'!$D$20:$H$20,B11) -> 1 | F11: =IF($N$18>0,INDEX('الخطة الفنية والإنتاج'!$D$22:$H$22,B11)*D11/$N$18,0) -> 29411.765 | G11: =IF($N$18>0,INDEX('الخطة الفنية والإنتاج'!$D$23:$H$23,B11)*D11/$N$18,0) -> 5882.3529 | H11: =IF($N$18>0,INDEX('الخطة الفنية والإنتاج'!$D$24:$H$24,B11)*D11/$N$18,0) -> 5000 | I11: =IF(D11>0,H11/D11,0) -> 192.30769 | J11: =SUM($H$6:H11) -> 30000 | K11: =OreReserve-SUM($G$6:G11) -> 364705.88 | M11: يونيو | N11: 26
A12: =EDATE($N$21,C12-1) -> 46844 | B12: =INT((C12-1)/12)+1 -> 1 | C12: 7 | D12: =INDEX($N$6:$N$17,MONTH(A12)) -> 26 | E12: =INDEX('الخطة الفنية والإنتاج'!$D$20:$H$20,B12) -> 1 | F12: =IF($N$18>0,INDEX('الخطة الفنية والإنتاج'!$D$22:$H$22,B12)*D12/$N$18,0) -> 29411.765 | G12: =IF($N$18>0,INDEX('الخطة الفنية والإنتاج'!$D$23:$H$23,B12)*D12/$N$18,0) -> 5882.3529 | H12: =IF($N$18>0,INDEX('الخطة الفنية والإنتاج'!$D$24:$H$24,B12)*D12/$N$18,0) -> 5000 | I12: =IF(D12>0,H12/D12,0) -> 192.30769 | J12: =SUM($H$6:H12) -> 35000 | K12: =OreReserve-SUM($G$6:G12) -> 358823.53 | M12: يوليو | N12: 26
A13: =EDATE($N$21,C13-1) -> 46874 | B13: =INT((C13-1)/12)+1 -> 1 | C13: 8 | D13: =INDEX($N$6:$N$17,MONTH(A13)) -> 26 | E13: =INDEX('الخطة الفنية والإنتاج'!$D$20:$H$20,B13) -> 1 | F13: =IF($N$18>0,INDEX('الخطة الفنية والإنتاج'!$D$22:$H$22,B13)*D13/$N$18,0) -> 29411.765 | G13: =IF($N$18>0,INDEX('الخطة الفنية والإنتاج'!$D$23:$H$23,B13)*D13/$N$18,0) -> 5882.3529 | H13: =IF($N$18>0,INDEX('الخطة الفنية والإنتاج'!$D$24:$H$24,B13)*D13/$N$18,0) -> 5000 | I13: =IF(D13>0,H13/D13,0) -> 192.30769 | J13: =SUM($H$6:H13) -> 40000 | K13: =OreReserve-SUM($G$6:G13) -> 352941.18 | M13: أغسطس | N13: 26
A14: =EDATE($N$21,C14-1) -> 46905 | B14: =INT((C14-1)/12)+1 -> 1 | C14: 9 | D14: =INDEX($N$6:$N$17,MONTH(A14)) -> 26 | E14: =INDEX('الخطة الفنية والإنتاج'!$D$20:$H$20,B14) -> 1 | F14: =IF($N$18>0,INDEX('الخطة الفنية والإنتاج'!$D$22:$H$22,B14)*D14/$N$18,0) -> 29411.765 | G14: =IF($N$18>0,INDEX('الخطة الفنية والإنتاج'!$D$23:$H$23,B14)*D14/$N$18,0) -> 5882.3529 | H14: =IF($N$18>0,INDEX('الخطة الفنية والإنتاج'!$D$24:$H$24,B14)*D14/$N$18,0) -> 5000 | I14: =IF(D14>0,H14/D14,0) -> 192.30769 | J14: =SUM($H$6:H14) -> 45000 | K14: =OreReserve-SUM($G$6:G14) -> 347058.82 | M14: سبتمبر | N14: 26
A15: =EDATE($N$21,C15-1) -> 46935 | B15: =INT((C15-1)/12)+1 -> 1 | C15: 10 | D15: =INDEX($N$6:$N$17,MONTH(A15)) -> 26 | E15: =INDEX('الخطة الفنية والإنتاج'!$D$20:$H$20,B15) -> 1 | F15: =IF($N$18>0,INDEX('الخطة الفنية والإنتاج'!$D$22:$H$22,B15)*D15/$N$18,0) -> 29411.765 | G15: =IF($N$18>0,INDEX('الخطة الفنية والإنتاج'!$D$23:$H$23,B15)*D15/$N$18,0) -> 5882.3529 | H15: =IF($N$18>0,INDEX('الخطة الفنية والإنتاج'!$D$24:$H$24,B15)*D15/$N$18,0) -> 5000 | I15: =IF(D15>0,H15/D15,0) -> 192.30769 | J15: =SUM($H$6:H15) -> 50000 | K15: =OreReserve-SUM($G$6:G15) -> 341176.47 | M15: أكتوبر | N15: 26
A16: =EDATE($N$21,C16-1) -> 46966 | B16: =INT((C16-1)/12)+1 -> 1 | C16: 11 | D16: =INDEX($N$6:$N$17,MONTH(A16)) -> 26 | E16: =INDEX('الخطة الفنية والإنتاج'!$D$20:$H$20,B16) -> 1 | F16: =IF($N$18>0,INDEX('الخطة الفنية والإنتاج'!$D$22:$H$22,B16)*D16/$N$18,0) -> 29411.765 | G16: =IF($N$18>0,INDEX('الخطة الفنية والإنتاج'!$D$23:$H$23,B16)*D16/$N$18,0) -> 5882.3529 | H16: =IF($N$18>0,INDEX('الخطة الفنية والإنتاج'!$D$24:$H$24,B16)*D16/$N$18,0) -> 5000 | I16: =IF(D16>0,H16/D16,0) -> 192.30769 | J16: =SUM($H$6:H16) -> 55000 | K16: =OreReserve-SUM($G$6:G16) -> 335294.12 | M16: نوفمبر | N16: 26
A17: =EDATE($N$21,C17-1) -> 46997 | B17: =INT((C17-1)/12)+1 -> 1 | C17: 12 | D17: =INDEX($N$6:$N$17,MONTH(A17)) -> 26 | E17: =INDEX('الخطة الفنية والإنتاج'!$D$20:$H$20,B17) -> 1 | F17: =IF($N$18>0,INDEX('الخطة الفنية والإنتاج'!$D$22:$H$22,B17)*D17/$N$18,0) -> 29411.765 | G17: =IF($N$18>0,INDEX('الخطة الفنية والإنتاج'!$D$23:$H$23,B17)*D17/$N$18,0) -> 5882.3529 | H17: =IF($N$18>0,INDEX('الخطة الفنية والإنتاج'!$D$24:$H$24,B17)*D17/$N$18,0) -> 5000 | I17: =IF(D17>0,H17/D17,0) -> 192.30769 | J17: =SUM($H$6:H17) -> 60000 | K17: =OreReserve-SUM($G$6:G17) -> 329411.76 | M17: ديسمبر | N17: 26
A18: =EDATE($N$21,C18-1) -> 47027 | B18: =INT((C18-1)/12)+1 -> 2 | C18: 13 | D18: =INDEX($N$6:$N$17,MONTH(A18)) -> 26 | E18: =INDEX('الخطة الفنية والإنتاج'!$D$20:$H$20,B18) -> 1 | F18: =IF($N$18>0,INDEX('الخطة الفنية والإنتاج'!$D$22:$H$22,B18)*D18/$N$18,0) -> 29411.765 | G18: =IF($N$18>0,INDEX('الخطة الفنية والإنتاج'!$D$23:$H$23,B18)*D18/$N$18,0) -> 5882.3529 | H18: =IF($N$18>0,INDEX('الخطة الفنية والإنتاج'!$D$24:$H$24,B18)*D18/$N$18,0) -> 5000 | I18: =IF(D18>0,H18/D18,0) -> 192.30769 | J18: =SUM($H$6:H18) -> 65000 | K18: =OreReserve-SUM($G$6:G18) -> 323529.41 | M18: مجموع أيام العمل في السنة | N18: =SUM(N6:N17) -> 312
A19: =EDATE($N$21,C19-1) -> 47058 | B19: =INT((C19-1)/12)+1 -> 2 | C19: 14 | D19: =INDEX($N$6:$N$17,MONTH(A19)) -> 26 | E19: =INDEX('الخطة الفنية والإنتاج'!$D$20:$H$20,B19) -> 1 | F19: =IF($N$18>0,INDEX('الخطة الفنية والإنتاج'!$D$22:$H$22,B19)*D19/$N$18,0) -> 29411.765 | G19: =IF($N$18>0,INDEX('الخطة الفنية والإنتاج'!$D$23:$H$23,B19)*D19/$N$18,0) -> 5882.3529 | H19: =IF($N$18>0,INDEX('الخطة الفنية والإنتاج'!$D$24:$H$24,B19)*D19/$N$18,0) -> 5000 | I19: =IF(D19>0,H19/D19,0) -> 192.30769 | J19: =SUM($H$6:H19) -> 70000 | K19: =OreReserve-SUM($G$6:G19) -> 317647.06 | M19: أيام العمل في ورقة «الافتراضات» | N19: =WorkDays -> 312
A20: =EDATE($N$21,C20-1) -> 47088 | B20: =INT((C20-1)/12)+1 -> 2 | C20: 15 | D20: =INDEX($N$6:$N$17,MONTH(A20)) -> 26 | E20: =INDEX('الخطة الفنية والإنتاج'!$D$20:$H$20,B20) -> 1 | F20: =IF($N$18>0,INDEX('الخطة الفنية والإنتاج'!$D$22:$H$22,B20)*D20/$N$18,0) -> 29411.765 | G20: =IF($N$18>0,INDEX('الخطة الفنية والإنتاج'!$D$23:$H$23,B20)*D20/$N$18,0) -> 5882.3529 | H20: =IF($N$18>0,INDEX('الخطة الفنية والإنتاج'!$D$24:$H$24,B20)*D20/$N$18,0) -> 5000 | I20: =IF(D20>0,H20/D20,0) -> 192.30769 | J20: =SUM($H$6:H20) -> 75000 | K20: =OreReserve-SUM($G$6:G20) -> 311764.71 | M20: التحقق | N20: =IF(N18=N19,"مطابق","المجموع يختلف عن «الافتراضات» — الإنتاج السنوي محسوب على أيام الافتراضات") -> مطابق
A21: =EDATE($N$21,C21-1) -> 47119 | B21: =INT((C21-1)/12)+1 -> 2 | C21: 16 | D21: =INDEX($N$6:$N$17,MONTH(A21)) -> 26 | E21: =INDEX('الخطة الفنية والإنتاج'!$D$20:$H$20,B21) -> 1 | F21: =IF($N$18>0,INDEX('الخطة الفنية والإنتاج'!$D$22:$H$22,B21)*D21/$N$18,0) -> 29411.765 | G21: =IF($N$18>0,INDEX('الخطة الفنية والإنتاج'!$D$23:$H$23,B21)*D21/$N$18,0) -> 5882.3529 | H21: =IF($N$18>0,INDEX('الخطة الفنية والإنتاج'!$D$24:$H$24,B21)*D21/$N$18,0) -> 5000 | I21: =IF(D21>0,H21/D21,0) -> 192.30769 | J21: =SUM($H$6:H21) -> 80000 | K21: =OreReserve-SUM($G$6:G21) -> 305882.35 | M21: شهر بدء الإنتاج (من «الجدول الزمني») | N21: =EDATE(StartDate,'الجدول الزمني'!$C$28-1) -> 46661
A22: =EDATE($N$21,C22-1) -> 47150 | B22: =INT((C22-1)/12)+1 -> 2 | C22: 17 | D22: =INDEX($N$6:$N$17,MONTH(A22)) -> 26 | E22: =INDEX('الخطة الفنية والإنتاج'!$D$20:$H$20,B22) -> 1 | F22: =IF($N$18>0,INDEX('الخطة الفنية والإنتاج'!$D$22:$H$22,B22)*D22/$N$18,0) -> 29411.765 | G22: =IF($N$18>0,INDEX('الخطة الفنية والإنتاج'!$D$23:$H$23,B22)*D22/$N$18,0) -> 5882.3529 | H22: =IF($N$18>0,INDEX('الخطة الفنية والإنتاج'!$D$24:$H$24,B22)*D22/$N$18,0) -> 5000 | I22: =IF(D22>0,H22/D22,0) -> 192.30769 | J22: =SUM($H$6:H22) -> 85000 | K22: =OreReserve-SUM($G$6:G22) -> 300000 | M22: عدّل أيام كل شهر لمراعاة رمضان والأعياد وحر الصيف؛ يُعاد توزيع الإنتاج السنوي فقط دون تغيير مجموعه.
A23: =EDATE($N$21,C23-1) -> 47178 | B23: =INT((C23-1)/12)+1 -> 2 | C23: 18 | D23: =INDEX($N$6:$N$17,MONTH(A23)) -> 26 | E23: =INDEX('الخطة الفنية والإنتاج'!$D$20:$H$20,B23) -> 1 | F23: =IF($N$18>0,INDEX('الخطة الفنية والإنتاج'!$D$22:$H$22,B23)*D23/$N$18,0) -> 29411.765 | G23: =IF($N$18>0,INDEX('الخطة الفنية والإنتاج'!$D$23:$H$23,B23)*D23/$N$18,0) -> 5882.3529 | H23: =IF($N$18>0,INDEX('الخطة الفنية والإنتاج'!$D$24:$H$24,B23)*D23/$N$18,0) -> 5000 | I23: =IF(D23>0,H23/D23,0) -> 192.30769 | J23: =SUM($H$6:H23) -> 90000 | K23: =OreReserve-SUM($G$6:G23) -> 294117.65
A24: =EDATE($N$21,C24-1) -> 47209 | B24: =INT((C24-1)/12)+1 -> 2 | C24: 19 | D24: =INDEX($N$6:$N$17,MONTH(A24)) -> 26 | E24: =INDEX('الخطة الفنية والإنتاج'!$D$20:$H$20,B24) -> 1 | F24: =IF($N$18>0,INDEX('الخطة الفنية والإنتاج'!$D$22:$H$22,B24)*D24/$N$18,0) -> 29411.765 | G24: =IF($N$18>0,INDEX('الخطة الفنية والإنتاج'!$D$23:$H$23,B24)*D24/$N$18,0) -> 5882.3529 | H24: =IF($N$18>0,INDEX('الخطة الفنية والإنتاج'!$D$24:$H$24,B24)*D24/$N$18,0) -> 5000 | I24: =IF(D24>0,H24/D24,0) -> 192.30769 | J24: =SUM($H$6:H24) -> 95000 | K24: =OreReserve-SUM($G$6:G24) -> 288235.29 | M24: ثالثاً: مطابقة الخام القابل للبيع مع الورقة السنوية
A25: =EDATE($N$21,C25-1) -> 47239 | B25: =INT((C25-1)/12)+1 -> 2 | C25: 20 | D25: =INDEX($N$6:$N$17,MONTH(A25)) -> 26 | E25: =INDEX('الخطة الفنية والإنتاج'!$D$20:$H$20,B25) -> 1 | F25: =IF($N$18>0,INDEX('الخطة الفنية والإنتاج'!$D$22:$H$22,B25)*D25/$N$18,0) -> 29411.765 | G25: =IF($N$18>0,INDEX('الخطة الفنية والإنتاج'!$D$23:$H$23,B25)*D25/$N$18,0) -> 5882.3529 | H25: =IF($N$18>0,INDEX('الخطة الفنية والإنتاج'!$D$24:$H$24,B25)*D25/$N$18,0) -> 5000 | I25: =IF(D25>0,H25/D25,0) -> 192.30769 | J25: =SUM($H$6:H25) -> 100000 | K25: =OreReserve-SUM($G$6:G25) -> 282352.94 | M25: سنة التشغيل | N25: مجموع الأشهر (طن) | O25: الورقة السنوية (طن) | P25: الفرق (طن)
A26: =EDATE($N$21,C26-1) -> 47270 | B26: =INT((C26-1)/12)+1 -> 2 | C26: 21 | D26: =INDEX($N$6:$N$17,MONTH(A26)) -> 26 | E26: =INDEX('الخطة الفنية والإنتاج'!$D$20:$H$20,B26) -> 1 | F26: =IF($N$18>0,INDEX('الخطة الفنية والإنتاج'!$D$22:$H$22,B26)*D26/$N$18,0) -> 29411.765 | G26: =IF($N$18>0,INDEX('الخطة الفنية والإنتاج'!$D$23:$H$23,B26)*D26/$N$18,0) -> 5882.3529 | H26: =IF($N$18>0,INDEX('الخطة الفنية والإنتاج'!$D$24:$H$24,B26)*D26/$N$18,0) -> 5000 | I26: =IF(D26>0,H26/D26,0) -> 192.30769 | J26: =SUM($H$6:H26) -> 105000 | K26: =OreReserve-SUM($G$6:G26) -> 276470.59 | M26: 1 | N26: =SUMIF($B$6:$B$65,M26,$H$6:$H$65) -> 60000 | O26: =INDEX('الخطة الفنية والإنتاج'!$D$24:$H$24,M26) -> 60000 | P26: =N26-O26 -> 0
A27: =EDATE($N$21,C27-1) -> 47300 | B27: =INT((C27-1)/12)+1 -> 2 | C27: 22 | D27: =INDEX($N$6:$N$17,MONTH(A27)) -> 26 | E27: =INDEX('الخطة الفنية والإنتاج'!$D$20:$H$20,B27) -> 1 | F27: =IF($N$18>0,INDEX('الخطة الفنية والإنتاج'!$D$22:$H$22,B27)*D27/$N$18,0) -> 29411.765 | G27: =IF($N$18>0,INDEX('الخطة الفنية والإنتاج'!$D$23:$H$23,B27)*D27/$N$18,0) -> 5882.3529 | H27: =IF($N$18>0,INDEX('الخطة الفنية والإنتاج'!$D$24:$H$24,B27)*D27/$N$18,0) -> 5000 | I27: =IF(D27>0,H27/D27,0) -> 192.30769 | J27: =SUM($H$6:H27) -> 110000 | K27: =OreReserve-SUM($G$6:G27) -> 270588.24 | M27: 2 | N27: =SUMIF($B$6:$B$65,M27,$H$6:$H$65) -> 60000 | O27: =INDEX('الخطة الفنية والإنتاج'!$D$24:$H$24,M27) -> 60000 | P27: =N27-O27 -> 0
A28: =EDATE($N$21,C28-1) -> 47331 | B28: =INT((C28-1)/12)+1 -> 2 | C28: 23 | D28: =INDEX($N$6:$N$17,MONTH(A28)) -> 26 | E28: =INDEX('الخطة الفنية والإنتاج'!$D$20:$H$20,B28) -> 1 | F28: =IF($N$18>0,INDEX('الخطة الفنية والإنتاج'!$D$22:$H$22,B28)*D28/$N$18,0) -> 29411.765 | G28: =IF($N$18>0,INDEX('الخطة الفنية والإنتاج'!$D$23:$H$23,B28)*D28/$N$18,0) -> 5882.3529 | H28: =IF($N$18>0,INDEX('الخطة الفنية والإنتاج'!$D$24:$H$24,B28)*D28/$N$18,0) -> 5000 | I28: =IF(D28>0,H28/D28,0) -> 192.30769 | J28: =SUM($H$6:H28) -> 115000 | K28: =OreReserve-SUM($G$6:G28) -> 264705.88 | M28: 3 | N28: =SUMIF($B$6:$B$65,M28,$H$6:$H$65) -> 60000 | O28: =INDEX('الخطة الفنية والإنتاج'!$D$24:$H$24,M28) -> 60000 | P28: =N28-O28 -> 0
A29: =EDATE($N$21,C29-1) -> 47362 | B29: =INT((C29-1)/12)+1 -> 2 | C29: 24 | D29: =INDEX($N$6:$N$17,MONTH(A29)) -> 26 | E29: =INDEX('الخطة الفنية والإنتاج'!$D$20:$H$20,B29) -> 1 | F29: =IF($N$18>0,INDEX('الخطة الفنية والإنتاج'!$D$22:$H$22,B29)*D29/$N$18,0) -> 29411.765 | G29: =IF($N$18>0,INDEX('الخطة الفنية والإنتاج'!$D$23:$H$23,B29)*D29/$N$18,0) -> 5882.3529 | H29: =IF($N$18>0,INDEX('الخطة الفنية والإنتاج'!$D$24:$H$24,B29)*D29/$N$18,0) -> 5000 | I29: =IF(D29>0,H29/D29,0) -> 192.30769 | J29: =SUM($H$6:H29) -> 120000 | K29: =OreReserve-SUM($G$6:G29) -> 258823.53 | M29: 4 | N29: =SUMIF($B$6:$B$65,M29,$H$6:$H$65) -> 60000 | O29: =INDEX('الخطة الفنية والإنتاج'!$D$24:$H$24,M29) -> 60000 | P29: =N29-O29 -> 0
A30: =EDATE($N$21,C30-1) -> 47392 | B30: =INT((C30-1)/12)+1 -> 3 | C30: 25 | D30: =INDEX($N$6:$N$17,MONTH(A30)) -> 26 | E30: =INDEX('الخطة الفنية والإنتاج'!$D$20:$H$20,B30) -> 1 | F30: =IF($N$18>0,INDEX('الخطة الفنية والإنتاج'!$D$22:$H$22,B30)*D30/$N$18,0) -> 29411.765 | G30: =IF($N$18>0,INDEX('الخطة الفنية والإنتاج'!$D$23:$H$23,B30)*D30/$N$18,0) -> 5882.3529 | H30: =IF($N$18>0,INDEX('الخطة الفنية والإنتاج'!$D$24:$H$24,B30)*D30/$N$18,0) -> 5000 | I30: =IF(D30>0,H30/D30,0) -> 192.30769 | J30: =SUM($H$6:H30) -> 125000 | K30: =OreReserve-SUM($G$6:G30) -> 252941.18 | M30: 5 | N30: =SUMIF($B$6:$B$65,M30,$H$6:$H$65) -> 60000 | O30: =INDEX('الخطة الفنية والإنتاج'!$D$24:$H$24,M30) -> 60000 | P30: =N30-O30 -> 0
A31: =EDATE($N$21,C31-1) -> 47423 | B31: =INT((C31-1)/12)+1 -> 3 | C31: 26 | D31: =INDEX($N$6:$N$17,MONTH(A31)) -> 26 | E31: =INDEX('الخطة الفنية والإنتاج'!$D$20:$H$20,B31) -> 1 | F31: =IF($N$18>0,INDEX('الخطة الفنية والإنتاج'!$D$22:$H$22,B31)*D31/$N$18,0) -> 29411.765 | G31: =IF($N$18>0,INDEX('الخطة الفنية والإنتاج'!$D$23:$H$23,B31)*D31/$N$18,0) -> 5882.3529 | H31: =IF($N$18>0,INDEX('الخطة الفنية والإنتاج'!$D$24:$H$24,B31)*D31/$N$18,0) -> 5000 | I31: =IF(D31>0,H31/D31,0) -> 192.30769 | J31: =SUM($H$6:H31) -> 130000 | K31: =OreReserve-SUM($G$6:G31) -> 247058.82 | M31: الإجمالي | N31: =SUM(N26:N30) -> 300000 | O31: =SUM(O26:O30) -> 300000 | P31: =SUM(P26:P30) -> 0
A32: =EDATE($N$21,C32-1) -> 47453 | B32: =INT((C32-1)/12)+1 -> 3 | C32: 27 | D32: =INDEX($N$6:$N$17,MONTH(A32)) -> 26 | E32: =INDEX('الخطة الفنية والإنتاج'!$D$20:$H$20,B32) -> 1 | F32: =IF($N$18>0,INDEX('الخطة الفنية والإنتاج'!$D$22:$H$22,B32)*D32/$N$18,0) -> 29411.765 | G32: =IF($N$18>0,INDEX('الخطة الفنية والإنتاج'!$D$23:$H$23,B32)*D32/$N$18,0) -> 5882.3529 | H32: =IF($N$18>0,INDEX('الخطة الفنية والإنتاج'!$D$24:$H$24,B32)*D32/$N$18,0) -> 5000 | I32: =IF(D32>0,H32/D32,0) -> 192.30769 | J32: =SUM($H$6:H32) -> 135000 | K32: =OreReserve-SUM($G$6:G32) -> 241176.47 | M32: النتيجة | N32: =IF(SUMPRODUCT(ABS(P26:P30))<0.5,"مطابق","يوجد فرق — راجع التوزيع") -> مطابق
A33: =EDATE($N$21,C33-1) -> 47484 | B33: =INT((C33-1)/12)+1 -> 3 | C33: 28 | D33: =INDEX($N$6:$N$17,MONTH(A33)) -> 26 | E33: =INDEX('الخطة الفنية والإنتاج'!$D$20:$H$20,B33) -> 1 | F33: =IF($N$18>0,INDEX('الخطة الفنية والإنتاج'!$D$22:$H$22,B33)*D33/$N$18,0) -> 29411.765 | G33: =IF($N$18>0,INDEX('الخطة الفنية والإنتاج'!$D$23:$H$23,B33)*D33/$N$18,0) -> 5882.3529 | H33: =IF($N$18>0,INDEX('الخطة الفنية والإنتاج'!$D$24:$H$24,B33)*D33/$N$18,0) -> 5000 | I33: =IF(D33>0,H33/D33,0) -> 192.30769 | J33: =SUM($H$6:H33) -> 140000 | K33: =OreReserve-SUM($G$6:G33) -> 235294.12
A34: =EDATE($N$21,C34-1) -> 47515 | B34: =INT((C34-1)/12)+1 -> 3 | C34: 29 | D34: =INDEX($N$6:$N$17,MONTH(A34)) -> 26 | E34: =INDEX('الخطة الفنية والإنتاج'!$D$20:$H$20,B34) -> 1 | F34: =IF($N$18>0,INDEX('الخطة الفنية والإنتاج'!$D$22:$H$22,B34)*D34/$N$18,0) -> 29411.765 | G34: =IF($N$18>0,INDEX('الخطة الفنية والإنتاج'!$D$23:$H$23,B34)*D34/$N$18,0) -> 5882.3529 | H34: =IF($N$18>0,INDEX('الخطة الفنية والإنتاج'!$D$24:$H$24,B34)*D34/$N$18,0) -> 5000 | I34: =IF(D34>0,H34/D34,0) -> 192.30769 | J34: =SUM($H$6:H34) -> 145000 | K34: =OreReserve-SUM($G$6:G34) -> 229411.76
A35: =EDATE($N$21,C35-1) -> 47543 | B35: =INT((C35-1)/12)+1 -> 3 | C35: 30 | D35: =INDEX($N$6:$N$17,MONTH(A35)) -> 26 | E35: =INDEX('الخطة الفنية والإنتاج'!$D$20:$H$20,B35) -> 1 | F35: =IF($N$18>0,INDEX('الخطة الفنية والإنتاج'!$D$22:$H$22,B35)*D35/$N$18,0) -> 29411.765 | G35: =IF($N$18>0,INDEX('الخطة الفنية والإنتاج'!$D$23:$H$23,B35)*D35/$N$18,0) -> 5882.3529 | H35: =IF($N$18>0,INDEX('الخطة الفنية والإنتاج'!$D$24:$H$24,B35)*D35/$N$18,0) -> 5000 | I35: =IF(D35>0,H35/D35,0) -> 192.30769 | J35: =SUM($H$6:H35) -> 150000 | K35: =OreReserve-SUM($G$6:G35) -> 223529.41
A36: =EDATE($N$21,C36-1) -> 47574 | B36: =INT((C36-1)/12)+1 -> 3 | C36: 31 | D36: =INDEX($N$6:$N$17,MONTH(A36)) -> 26 | E36: =INDEX('الخطة الفنية والإنتاج'!$D$20:$H$20,B36) -> 1 | F36: =IF($N$18>0,INDEX('الخطة الفنية والإنتاج'!$D$22:$H$22,B36)*D36/$N$18,0) -> 29411.765 | G36: =IF($N$18>0,INDEX('الخطة الفنية والإنتاج'!$D$23:$H$23,B36)*D36/$N$18,0) -> 5882.3529 | H36: =IF($N$18>0,INDEX('الخطة الفنية والإنتاج'!$D$24:$H$24,B36)*D36/$N$18,0) -> 5000 | I36: =IF(D36>0,H36/D36,0) -> 192.30769 | J36: =SUM($H$6:H36) -> 155000 | K36: =OreReserve-SUM($G$6:G36) -> 217647.06
A37: =EDATE($N$21,C37-1) -> 47604 | B37: =INT((C37-1)/12)+1 -> 3 | C37: 32 | D37: =INDEX($N$6:$N$17,MONTH(A37)) -> 26 | E37: =INDEX('الخطة الفنية والإنتاج'!$D$20:$H$20,B37) -> 1 | F37: =IF($N$18>0,INDEX('الخطة الفنية والإنتاج'!$D$22:$H$22,B37)*D37/$N$18,0) -> 29411.765 | G37: =IF($N$18>0,INDEX('الخطة الفنية والإنتاج'!$D$23:$H$23,B37)*D37/$N$18,0) -> 5882.3529 | H37: =IF($N$18>0,INDEX('الخطة الفنية والإنتاج'!$D$24:$H$24,B37)*D37/$N$18,0) -> 5000 | I37: =IF(D37>0,H37/D37,0) -> 192.30769 | J37: =SUM($H$6:H37) -> 160000 | K37: =OreReserve-SUM($G$6:G37) -> 211764.71
A38: =EDATE($N$21,C38-1) -> 47635 | B38: =INT((C38-1)/12)+1 -> 3 | C38: 33 | D38: =INDEX($N$6:$N$17,MONTH(A38)) -> 26 | E38: =INDEX('الخطة الفنية والإنتاج'!$D$20:$H$20,B38) -> 1 | F38: =IF($N$18>0,INDEX('الخطة الفنية والإنتاج'!$D$22:$H$22,B38)*D38/$N$18,0) -> 29411.765 | G38: =IF($N$18>0,INDEX('الخطة الفنية والإنتاج'!$D$23:$H$23,B38)*D38/$N$18,0) -> 5882.3529 | H38: =IF($N$18>0,INDEX('الخطة الفنية والإنتاج'!$D$24:$H$24,B38)*D38/$N$18,0) -> 5000 | I38: =IF(D38>0,H38/D38,0) -> 192.30769 | J38: =SUM($H$6:H38) -> 165000 | K38: =OreReserve-SUM($G$6:G38) -> 205882.35
A39: =EDATE($N$21,C39-1) -> 47665 | B39: =INT((C39-1)/12)+1 -> 3 | C39: 34 | D39: =INDEX($N$6:$N$17,MONTH(A39)) -> 26 | E39: =INDEX('الخطة الفنية والإنتاج'!$D$20:$H$20,B39) -> 1 | F39: =IF($N$18>0,INDEX('الخطة الفنية والإنتاج'!$D$22:$H$22,B39)*D39/$N$18,0) -> 29411.765 | G39: =IF($N$18>0,INDEX('الخطة الفنية والإنتاج'!$D$23:$H$23,B39)*D39/$N$18,0) -> 5882.3529 | H39: =IF($N$18>0,INDEX('الخطة الفنية والإنتاج'!$D$24:$H$24,B39)*D39/$N$18,0) -> 5000 | I39: =IF(D39>0,H39/D39,0) -> 192.30769 | J39: =SUM($H$6:H39) -> 170000 | K39: =OreReserve-SUM($G$6:G39) -> 200000
A40: =EDATE($N$21,C40-1) -> 47696 | B40: =INT((C40-1)/12)+1 -> 3 | C40: 35 | D40: =INDEX($N$6:$N$17,MONTH(A40)) -> 26 | E40: =INDEX('الخطة الفنية والإنتاج'!$D$20:$H$20,B40) -> 1 | F40: =IF($N$18>0,INDEX('الخطة الفنية والإنتاج'!$D$22:$H$22,B40)*D40/$N$18,0) -> 29411.765 | G40: =IF($N$18>0,INDEX('الخطة الفنية والإنتاج'!$D$23:$H$23,B40)*D40/$N$18,0) -> 5882.3529 | H40: =IF($N$18>0,INDEX('الخطة الفنية والإنتاج'!$D$24:$H$24,B40)*D40/$N$18,0) -> 5000 | I40: =IF(D40>0,H40/D40,0) -> 192.30769 | J40: =SUM($H$6:H40) -> 175000 | K40: =OreReserve-SUM($G$6:G40) -> 194117.65
A41: =EDATE($N$21,C41-1) -> 47727 | B41: =INT((C41-1)/12)+1 -> 3 | C41: 36 | D41: =INDEX($N$6:$N$17,MONTH(A41)) -> 26 | E41: =INDEX('الخطة الفنية والإنتاج'!$D$20:$H$20,B41) -> 1 | F41: =IF($N$18>0,INDEX('الخطة الفنية والإنتاج'!$D$22:$H$22,B41)*D41/$N$18,0) -> 29411.765 | G41: =IF($N$18>0,INDEX('الخطة الفنية والإنتاج'!$D$23:$H$23,B41)*D41/$N$18,0) -> 5882.3529 | H41: =IF($N$18>0,INDEX('الخطة الفنية والإنتاج'!$D$24:$H$24,B41)*D41/$N$18,0) -> 5000 | I41: =IF(D41>0,H41/D41,0) -> 192.30769 | J41: =SUM($H$6:H41) -> 180000 | K41: =OreReserve-SUM($G$6:G41) -> 188235.29
...

Sheet الجدول الزمني
A1: مراحل وخطة تنفيذ المشروع
A2: التسلسل الصحيح: استكشاف ← دراسات وتراخيص ← تمويل وتجهيز ← تأهيل الموقع ← إنتاج. المدد تقديرية وتُعدَّل من عمودي «شهر البداية» و«المدة»
A4: المهمة | B4: الجهة / التفاصيل | C4: شهر البداية | D4: المدة (شهر) | E4: تاريخ البداية | F4: تاريخ النهاية | G4: 1 | H4: 2 | I4: 3 | J4: 4 | K4: 5 | L4: 6 | M4: 7 | N4: 8 | O4: 9 | P4: 10 | Q4: 11 | R4: 12
A5: المرحلة التمهيدية — الاستكشاف (منجزة)
A6: ترخيص التنقيب والتصريح البيئي للتنقيب | B6: وزارة الطاقة والمعادن / هيئة البيئة — منجز
A7: فتح الطريق وأعمال التنقيب وأخذ العينات | B7: منجز خلال السنوات الثلاث الماضية (مصاريف مدفوعة سابقاً)
A8: المرحلة الأولى — الدراسات والتراخيص
A9: التقرير الاستكشافي وتقدير الاحتياطي والدرجة | B9: جيولوجي معتمد / مختبر تحاليل | C9: 1 | D9: 2 | E9: =IF($D9>0,EDATE(StartDate,$C9-1),"") -> 46388 | F9: =IF($D9>0,EDATE(StartDate,$C9-1+$D9)-1,"") -> 46446
A10: دراسة الجدوى وخطة التعدين والمخططات الهندسية | B10: مكتب استشاري | C10: 1 | D10: 2 | E10: =IF($D10>0,EDATE(StartDate,$C10-1),"") -> 46388 | F10: =IF($D10>0,EDATE(StartDate,$C10-1+$D10)-1,"") -> 46446
A11: دراسة الأثر البيئي والتصريح البيئي للتعدين | B11: هيئة البيئة | C11: 2 | D11: 3 | E11: =IF($D11>0,EDATE(StartDate,$C11-1),"") -> 46419 | F11: =IF($D11>0,EDATE(StartDate,$C11-1+$D11)-1,"") -> 46507
A12: طلب ترخيص التعدين وموافقات الجهات المختصة | B12: وزارة الطاقة والمعادن | C12: 3 | D12: 4 | E12: =IF($D12>0,EDATE(StartDate,$C12-1),"") -> 46447 | F12: =IF($D12>0,EDATE(StartDate,$C12-1+$D12)-1,"") -> 46568
A13: تقديم الضمانات البنكية | B13: البنك / وزارة الطاقة والمعادن / هيئة البيئة | C13: 6 | D13: 1 | E13: =IF($D13>0,EDATE(StartDate,$C13-1),"") -> 46539 | F13: =IF($D13>0,EDATE(StartDate,$C13-1+$D13)-1,"") -> 46568
A14: الترخيص البلدي | B14: بلدية شمال الشرقية | C14: 6 | D14: 1 | E14: =IF($D14>0,EDATE(StartDate,$C14-1),"") -> 46539 | F14: =IF($D14>0,EDATE(StartDate,$C14-1+$D14)-1,"") -> 46568
A15: المرحلة الثانية — التمويل والتجهيز | E15: =IF($D15>0,EDATE(StartDate,$C15-1),"") | F15: =IF($D15>0,EDATE(StartDate,$C15-1+$D15)-1,"")
A16: اعتماد التمويل وتوقيع عقد القرض | B16: الجهة الممولة | C16: 5 | D16: 2 | E16: =IF($D16>0,EDATE(StartDate,$C16-1),"") -> 46508 | F16: =IF($D16>0,EDATE(StartDate,$C16-1+$D16)-1,"") -> 46568
A17: التعاقد على بيع وتسويق الخام | B17: شركة متاجرة المعادن / مشترون محليون | C17: 6 | D17: 2 | E17: =IF($D17>0,EDATE(StartDate,$C17-1),"") -> 46539 | F17: =IF($D17>0,EDATE(StartDate,$C17-1+$D17)-1,"") -> 46599
A18: استئجار السكن والمكتب وموقع التجميع | B18: 3 مواقع | C18: 7 | D18: 1 | E18: =IF($D18>0,EDATE(StartDate,$C18-1),"") -> 46569 | F18: =IF($D18>0,EDATE(StartDate,$C18-1+$D18)-1,"") -> 46599
A19: توظيف الكادر العُماني | B19: مدير، محاسب، جيولوجي، مشرفان، سائق، 4 حراس | C19: 7 | D19: 2 | E19: =IF($D19>0,EDATE(StartDate,$C19-1),"") -> 46569 | F19: =IF($D19>0,EDATE(StartDate,$C19-1+$D19)-1,"") -> 46630
A20: استخراج مأذونيات العمالة الوافدة والتأشيرات | B20: ="وزارة العمل / شرطة عُمان السلطانية — "&'الموارد البشرية'!B21&" عاملاً" -> وزارة العمل / شرطة عُمان السلطانية — 8 عاملاً | C20: 7 | D20: 2 | E20: =IF($D20>0,EDATE(StartDate,$C20-1),"") -> 46569 | F20: =IF($D20>0,EDATE(StartDate,$C20-1+$D20)-1,"") -> 46630
A21: شراء الشيول والقلاب والبيك أب | B21: معدات مملوكة | C21: 7 | D21: 2 | E21: =IF($D21>0,EDATE(StartDate,$C21-1),"") -> 46569 | F21: =IF($D21>0,EDATE(StartDate,$C21-1+$D21)-1,"") -> 46630
A22: شراء معدات الأمن والسلامة والأجهزة والأثاث | B22: — | C22: 8 | D22: 1 | E22: =IF($D22>0,EDATE(StartDate,$C22-1),"") -> 46600 | F22: =IF($D22>0,EDATE(StartDate,$C22-1+$D22)-1,"") -> 46630
A23: التعاقد على استئجار الحفارات والمولد | B23: 5 حفارات بالساعة شاملة المشغل والديزل + مولد | C23: 9 | D23: 1 | E23: =IF($D23>0,EDATE(StartDate,$C23-1),"") -> 46631 | F23: =IF($D23>0,EDATE(StartDate,$C23-1+$D23)-1,"") -> 46660
A24: المرحلة الثالثة — تأهيل الموقع | E24: =IF($D24>0,EDATE(StartDate,$C24-1),"") | F24: =IF($D24>0,EDATE(StartDate,$C24-1+$D24)-1,"")
A25: تأهيل الطريق المؤدي إلى الموقع | B25: — | C25: 8 | D25: 1 | E25: =IF($D25>0,EDATE(StartDate,$C25-1),"") -> 46600 | F25: =IF($D25>0,EDATE(StartDate,$C25-1+$D25)-1,"") -> 46630
A26: تجهيز الموقع وإزالة الغطاء الصخري (التعرية الأولية) | B26: — | C26: 8 | D26: 2 | E26: =IF($D26>0,EDATE(StartDate,$C26-1),"") -> 46600 | F26: =IF($D26>0,EDATE(StartDate,$C26-1+$D26)-1,"") -> 46660
A27: المرحلة الرابعة — الإنتاج | E27: =IF($D27>0,EDATE(StartDate,$C27-1),"") | F27: =IF($D27>0,EDATE(StartDate,$C27-1+$D27)-1,"")
A28: الإنتاج التجريبي ثم التجاري (بداية السنة الأولى في الدراسة) | B28: بيع أولى الشحنات | C28: 10 | D28: 3 | E28: =IF($D28>0,EDATE(StartDate,$C28-1),"") -> 46661 | F28: =IF($D28>0,EDATE(StartDate,$C28-1+$D28)-1,"") -> 46752
A30: مدة التأسيس حتى بدء الإنتاج | C30: =C28-1 -> 9 | D30: شهر
A31: ملاحظة: مدة إصدار ترخيص التعدين تتفاوت كثيراً بحسب موافقات الجهات المختصة — يُنصح بهامش زمني إضافي عند الالتزام مع الممولين والمورّدين.

Sheet الأصول والإهلاك
A1: الأصول الثابتة وجدول الإهلاك
A2: إهلاك بطريقة القسط الثابت. الحفارات مستأجرة بالساعة (انظر «الإيجارات»)؛ الشيول والقلاب والبيك أب مملوكة
A4: الأصل | B4: العدد | C4: سعر الوحدة (ر.ع) | D4: التكلفة الإجمالية | E4: العمر الإنتاجي (سنة) | F4: القيمة التخريدية % | G4: يُستبدل عند انتهاء العمر (1 = نعم) | H4: الإهلاك السنوي | I4: المصدر / ملاحظات
A5: شيول (لودر بعجلات) | B5: 1 | C5: 50000 | D5: =B5*C5*F_Capex -> 50000 | E5: 7 | F5: 0.15 | G5: 0 | H5: =IF(E5>0,D5*(1-F5)/E5,0) -> 6071.4286 | I5: شراء بقرار المالك — السعر افتراض يُؤكَّد بعروض الوكلاء
A6: قلاب (تيبر) لنقل الخام | B6: 1 | C6: 32000 | D6: =B6*C6*F_Capex -> 32000 | E6: 7 | F6: 0.15 | G6: 0 | H6: =IF(E6>0,D6*(1-F6)/E6,0) -> 3885.7143 | I6: شراء بقرار المالك — السعر افتراض يُؤكَّد بعروض الوكلاء
A7: سيارة بيك أب دفع رباعي | B7: 1 | C7: 11000 | D7: =B7*C7*F_Capex -> 11000 | E7: 5 | F7: 0.2 | G7: 0 | H7: =IF(E7>0,D7*(1-F7)/E7,0) -> 1760 | I7: شراء بقرار المالك — السعر افتراض يُؤكَّد بعرض
A8: أثاث وتجهيزات المكتب والسكن | B8: 1 | C8: 4000 | D8: =B8*C8*F_Capex -> 4000 | E8: 5 | F8: 0 | G8: 0 | H8: =IF(E8>0,D8*(1-F8)/E8,0) -> 800 | I8: 4,000 من الدراسة الأصلية
A9: معدات الأمن والسلامة والأجهزة | B9: 1 | C9: 3500 | D9: =B9*C9*F_Capex -> 3500 | E9: 5 | F9: 0 | G9: 0 | H9: =IF(E9>0,D9*(1-F9)/E9,0) -> 700 | I9: افتراض يُؤكَّد بعرض سعر
A10: إجمالي الأصول الثابتة | D10: =SUM(D5:D9) -> 100500 | H10: =SUM(H5:H9) -> 13217.143
A11: منها: المعدات والمركبات المتحركة | D11: =SUM(D5:D7) -> 93000 | I11: أساس احتساب الصيانة والتأمين
A13: جدول الإهلاك والاستبدال | B13: الوحدة | C13: 0 | D13: 1 | E13: 2 | F13: 3 | G13: 4 | H13: 5 | I13: الإجمالي
A14: إهلاك شيول (لودر بعجلات) | B14: ر.ع | D14: =IF(OR(D$13<=$E$5,$G$5=1),$H$5,0) -> 6071.4286 | E14: =IF(OR(E$13<=$E$5,$G$5=1),$H$5,0) -> 6071.4286 | F14: =IF(OR(F$13<=$E$5,$G$5=1),$H$5,0) -> 6071.4286 | G14: =IF(OR(G$13<=$E$5,$G$5=1),$H$5,0) -> 6071.4286 | H14: =IF(OR(H$13<=$E$5,$G$5=1),$H$5,0) -> 6071.4286 | I14: =SUM(D14:H14) -> 30357.143
A15: إهلاك قلاب (تيبر) لنقل الخام | B15: ر.ع | D15: =IF(OR(D$13<=$E$6,$G$6=1),$H$6,0) -> 3885.7143 | E15: =IF(OR(E$13<=$E$6,$G$6=1),$H$6,0) -> 3885.7143 | F15: =IF(OR(F$13<=$E$6,$G$6=1),$H$6,0) -> 3885.7143 | G15: =IF(OR(G$13<=$E$6,$G$6=1),$H$6,0) -> 3885.7143 | H15: =IF(OR(H$13<=$E$6,$G$6=1),$H$6,0) -> 3885.7143 | I15: =SUM(D15:H15) -> 19428.571
A16: إهلاك سيارة بيك أب دفع رباعي | B16: ر.ع | D16: =IF(OR(D$13<=$E$7,$G$7=1),$H$7,0) -> 1760 | E16: =IF(OR(E$13<=$E$7,$G$7=1),$H$7,0) -> 1760 | F16: =IF(OR(F$13<=$E$7,$G$7=1),$H$7,0) -> 1760 | G16: =IF(OR(G$13<=$E$7,$G$7=1),$H$7,0) -> 1760 | H16: =IF(OR(H$13<=$E$7,$G$7=1),$H$7,0) -> 1760 | I16: =SUM(D16:H16) -> 8800
A17: إهلاك أثاث وتجهيزات المكتب والسكن | B17: ر.ع | D17: =IF(OR(D$13<=$E$8,$G$8=1),$H$8,0) -> 800 | E17: =IF(OR(E$13<=$E$8,$G$8=1),$H$8,0) -> 800 | F17: =IF(OR(F$13<=$E$8,$G$8=1),$H$8,0) -> 800 | G17: =IF(OR(G$13<=$E$8,$G$8=1),$H$8,0) -> 800 | H17: =IF(OR(H$13<=$E$8,$G$8=1),$H$8,0) -> 800 | I17: =SUM(D17:H17) -> 4000
A18: إهلاك معدات الأمن والسلامة والأجهزة | B18: ر.ع | D18: =IF(OR(D$13<=$E$9,$G$9=1),$H$9,0) -> 700 | E18: =IF(OR(E$13<=$E$9,$G$9=1),$H$9,0) -> 700 | F18: =IF(OR(F$13<=$E$9,$G$9=1),$H$9,0) -> 700 | G18: =IF(OR(G$13<=$E$9,$G$9=1),$H$9,0) -> 700 | H18: =IF(OR(H$13<=$E$9,$G$9=1),$H$9,0) -> 700 | I18: =SUM(D18:H18) -> 3500
A19: إجمالي الإهلاك السنوي | B19: ر.ع | D19: =SUM(D14:D18) -> 13217.143 | E19: =SUM(E14:E18) -> 13217.143 | F19: =SUM(F14:F18) -> 13217.143 | G19: =SUM(G14:G18) -> 13217.143 | H19: =SUM(H14:H18) -> 13217.143 | I19: =SUM(D19:H19) -> 66085.714
A20: استبدال الأصول (نفقات رأسمالية) | B20: ر.ع | D20: =IF(AND($G$5=1,D$13=$E$5+1),$D$5,0)+IF(AND($G$6=1,D$13=$E$6+1),$D$6,0)+IF(AND($G$7=1,D$13=$E$7+1),$D$7,0)+IF(AND($G$8=1,D$13=$E$8+1),$D$8,0)+IF(AND($G$9=1,D$13=$E$9+1),$D$9,0) -> 0 | E20: =IF(AND($G$5=1,E$13=$E$5+1),$D$5,0)+IF(AND($G$6=1,E$13=$E$6+1),$D$6,0)+IF(AND($G$7=1,E$13=$E$7+1),$D$7,0)+IF(AND($G$8=1,E$13=$E$8+1),$D$8,0)+IF(AND($G$9=1,E$13=$E$9+1),$D$9,0) -> 0 | F20: =IF(AND($G$5=1,F$13=$E$5+1),$D$5,0)+IF(AND($G$6=1,F$13=$E$6+1),$D$6,0)+IF(AND($G$7=1,F$13=$E$7+1),$D$7,0)+IF(AND($G$8=1,F$13=$E$8+1),$D$8,0)+IF(AND($G$9=1,F$13=$E$9+1),$D$9,0) -> 0 | G20: =IF(AND($G$5=1,G$13=$E$5+1),$D$5,0)+IF(AND($G$6=1,G$13=$E$6+1),$D$6,0)+IF(AND($G$7=1,G$13=$E$7+1),$D$7,0)+IF(AND($G$8=1,G$13=$E$8+1),$D$8,0)+IF(AND($G$9=1,G$13=$E$9+1),$D$9,0) -> 0 | H20: =IF(AND($G$5=1,H$13=$E$5+1),$D$5,0)+IF(AND($G$6=1,H$13=$E$6+1),$D$6,0)+IF(AND($G$7=1,H$13=$E$7+1),$D$7,0)+IF(AND($G$8=1,H$13=$E$8+1),$D$8,0)+IF(AND($G$9=1,H$13=$E$9+1),$D$9,0) -> 0 | I20: =SUM(D20:H20) -> 0
A21: الأصول بالتكلفة (تراكمي) | B21: ر.ع | C21: =D10 -> 100500 | D21: =C21+D20 -> 100500 | E21: =D21+E20 -> 100500 | F21: =E21+F20 -> 100500 | G21: =F21+G20 -> 100500 | H21: =G21+H20 -> 100500
A22: مجمع الإهلاك | B22: ر.ع | C22: 0 | D22: =C22+D19 -> 13217.143 | E22: =D22+E19 -> 26434.286 | F22: =E22+F19 -> 39651.429 | G22: =F22+G19 -> 52868.571 | H22: =G22+H19 -> 66085.714
A23: صافي القيمة الدفترية آخر السنة | B23: ر.ع | C23: =C21-C22 -> 100500 | D23: =D21-D22 -> 87282.857 | E23: =E21-E22 -> 74065.714 | F23: =F21-F22 -> 60848.571 | G23: =G21-G22 -> 47631.429 | H23: =H21-H22 -> 34414.286
A24: صافي القيمة الدفترية في نهاية السنة الخامسة يُدرج كقيمة تخريدية في التدفقات النقدية.

Sheet مصاريف ما قبل التشغيل
A1: مصاريف ما قبل التشغيل
A2: تُرسمل وتُطفأ على سنوات التشغيل. الضمانات البنكية نُقلت إلى التكلفة الاستثمارية كوديعة مستردة
A4: البيان | B4: القيمة (ر.ع) | C4: الحالة | D4: ملاحظات
A5: رسوم التراخيص اللازمة للمشروع | B5: =LicFees -> 8400 | C5: محتسب | D5: من ورقة «التراخيص» (كان رابطاً خارجياً مكسوراً يعطي صفراً في الملف الأصلي)
A6: الاستشارات الإدارية والمالية والفنية | B6: 12200 | C6: من الدراسة الأصلية
A7: المخططات الهندسية والتصميمية | B7: 5600 | C7: من الدراسة الأصلية
A8: تكلفة مأذونيات استقدام العمالة الوافدة | B8: =PermitCost -> 2028 | C8: محتسب | D8: من ورقة «الموارد البشرية» وفق رسوم وزارة العمل (الملف الأصلي ذكر 3,420 في ورقة و2,420 في أخرى)
A9: مصاريف الاستكشاف وفتح الطريق والمعدات المدفوعة خلال السنوات الثلاث الماضية | B9: 200000 | C9: يحتاج تأكيداً | D9: الملف الأصلي ذكر 200,000 في ورقة و257,000 في أخرى — اعتُمد 200,000 ويجب تأكيد الرقم الصحيح بالمستندات
A10: الإجمالي | B10: =SUM(B5:B9) -> 228228
A12: مدة الإطفاء | B12: 5 | C12: سنة | D12: على مدة الدراسة (5 سنوات تشغيل)
A13: الإطفاء السنوي | B13: =PreOp/AmortYrs -> 45645.6 | C13: ر.ع / سنة

Sheet الموارد البشرية
A1: الموارد البشرية — الأجور والرواتب والتأمينات
A2: الوظائف والأعداد والرواتب من الدراسة الأصلية (مع تصحيح راتب الحارس إلى الحد الأدنى للأجور)
A4: الوظيفة | B4: الفئة | C4: الجنسية | D4: العدد | E4: الراتب الشهري (ر.ع) | F4: إجمالي الرواتب الشهرية | G4: الإجمالي السنوي | H4: فئة مأذونية العمل | I4: ملاحظات
